Workbook

Sheet DATA ASLI
A2: Kode | B2: Nama Indikator | C2: Pilar | D2: Satuan | E2: Target 2025 | F2: Target 2026 | G2: Target 2027 | H2: Target 2028 | I2: Target 2029 | J2: Capaian 2025 | K2: Capaian 2026 | L2: Capaian 2027 | M2: Capaian 2028 | N2: Capaian 2029 | O2: Gap Capaian 2025
A3: P1-01 | B3: Total Fertility Rate (TFR) | C3: Pilar 1: Kuantitas Penduduk | D3: Anak/WUS | E3: 1.82 | F3: 1.83 | G3: 1.84 | H3: 1.85 | I3: 1.85 | J3: 1.96 | O3: =SUM(J3-E3) -> 0.14
A4: P1-02 | B4: ASFR 15-19 Tahun | C4: Pilar 1: Kuantitas Penduduk | D4: /1000 WUS | E4: 17.29 | F4: 17 | G4: 17 | H4: 17 | I4: 17 | J4: 14.4 | O4: =SUM(J4-E4) -> -2.89
A5: P1-03 | B5: Proporsi KB Modern | C5: Pilar 1: Kuantitas Penduduk | D5: % | E5: 77 | F5: 77 | G5: 77 | H5: 77 | I5: 77 | J5: 92.4 | O5: =SUM(J5-E5) -> 15.4
A6: P2-04 | B6: Rata-Rata Lama Sekolah (RLS) | C6: Pilar 2: Kualitas Penduduk | D6: Tahun
A7: P2-05 | B7: APK Perguruan Tinggi | C7: Pilar 2: Kualitas Penduduk | D7: %
A8: P2-06 | B8: Pekerja Lulusan Sesuai Bidang | C8: Pilar 2: Kualitas Penduduk | D8: %
A9: P2-07 | B9: Prevalensi Stunting | C9: Pilar 2: Kualitas Penduduk | D9: % | E9: 4.34 | F9: 4.27 | G9: 4.24 | H9: 4.22 | I9: 4.15
A10: P2-08 | B10: Angka Kematian Bayi (AKB) | C10: Pilar 2: Kualitas Penduduk | D10: /1000 KH | E10: 11.2 | F10: 11 | G10: 10.8 | H10: 10.6 | I10: 10.4
A11: P2-09 | B11: Angka Kematian Ibu (AKI) | C11: Pilar 2: Kualitas Penduduk | D11: /100.000 KH | E11: 106 | F11: 105 | G11: 104 | H11: 103 | I11: 102
A12: P2-10 | B12: Tingkat Kemiskinan | C12: Pilar 2: Kualitas Penduduk | D12: % | E12: 8.38 | F12: 8.12 | G12: 7.85 | H12: 7.58 | I12: 7.31
A13: P2-11 | B13: TPAK Perempuan | C13: Pilar 2: Kualitas Penduduk | D13: % | E13: 54.41 | F13: 55.29 | G13: 56.18 | H13: 57.06 | I13: 57.95
A14: P2-12 | B14: Pekerja Informal | C14: Pilar 2: Kualitas Penduduk | D14: % | E14: 6.3 | F14: 6.31 | G14: 6.32 | H14: 6.33 | I14: 6.34
A15: P2-13 | B15: Penyandang Disabilitas Formal | C15: Pilar 2: Kualitas Penduduk | D15: % | E15: 0.024 | F15: 0.025 | G15: 0.026 | H15: 0.027 | I15: 0.028
A16: P2-14 | B16: Gini Ratio | C16: Pilar 2: Kualitas Penduduk | D16: Indeks | E16: 0.352 | F16: 0.341 | G16: 0.33 | H16: 0.319 | I16: 0.308
A17: P2-15 | B17: PDRB Per Kapita | C17: Pilar 2: Kualitas Penduduk | D17: Rp Juta
A18: P2-16 | B18: TPT (Pengangguran Terbuka) | C18: Pilar 2: Kualitas Penduduk | D18: % | E18: 3,38-2,38 | F18: 3.03 | G18: 2.96 | H18: 2.89 | I18: 2.82
A19: P2-17 | B19: Penambahan Wajib Pajak | C19: Pilar 2: Kualitas Penduduk | D19: %
A20: P3-18 | B20: Indeks iBangga | C20: Pilar 3: Pembangunan Keluarga | D20: Indeks | E20: 60.5 | F20: 61 | G20: 61.5 | H20: 62 | I20: 62.5 | J20: 60.3 | O20: =SUM(J20-E20) -> -0.2
A21: P3-19 | B21: Indeks Perlindungan Anak | C21: Pilar 3: Pembangunan Keluarga | D21: Indeks | E21: 63.9 | F21: 64.1 | G21: 65.1 | H21: 66.1 | I21: 68.1
A22: P3-20 | B22: RT Akses Hunian Layak | C22: Pilar 3: Pembangunan Keluarga | D22: % | E22: 17.35 | F22: 18.21 | G22: 19.03 | H22: 19.81 | I22: 20.49
A23: P3-21 | B23: RT Akses Sanitasi Aman | C23: Pilar 3: Pembangunan Keluarga | D23: % | E23: 6.82 | F23: 7.13 | G23: 8.02 | H23: 9.31 | I23: 10.51
A24: P3-22 | B24: Indeks Lansia Berdaya | C24: Pilar 3: Pembangunan Keluarga | D24: Indeks | E24: 57.6 | F24: 57.6 | G24: 57.6 | H24: 57.6 | I24: 57.6 | J24: 70.2 | O24: =J24-E24 -> 12.6
A25: P3-23 | B25: Indeks Pengasuhan Remaja | C25: Pilar 3: Pembangunan Keluarga | D25: Indeks | E25: 79.9 | F25: 79.9 | G25: 79.9 | H25: 79.9 | I25: 79.9 | J25: 80.3 | O25: =J25-E25 -> 0.4
A26: P3-24 | B26: Cakupan JKN | C26: Pilar 3: Pembangunan Keluarga | D26: % | E26: 87.36 | F26: 89.27 | G26: 91.18 | H26: 93.09 | I26: 95
A27: P4-25 | B27: Kampung KB Mandiri | C27: Pilar 4: Persebaran Penduduk | D27: % | E27: 8.8 | F27: 10 | G27: 20 | H27: 30 | I27: 40
A28: P4-26 | B28: Kepadatan Penduduk | C28: Pilar 4: Persebaran Penduduk | D28: Jiwa/km² | E28: 628.28 | F28: 633.8 | G28: 638.7 | H28: 642.5 | I28: 645.3 | J28: 645 | O28: =SUM(J28-E28) -> 16.72
A29: P5-27 | B29: Akta Kelahiran Balita | C29: Pilar 5: Administrasi Kependudukan | D29: % | E29: 99.55 | F29: 99.64 | G29: 99.73 | H29: 99.81 | I29: 99.9
A30: P5-28 | B30: Akta Cerai | C30: Pilar 5: Administrasi Kependudukan | D30: % | E30: 100 | F30: 100 | G30: 100 | H30: 100 | I30: 100
A31: P5-29 | B31: Akta Nikah | C31: Pilar 5: Administrasi Kependudukan | D31: % | E31: 100 | F31: 100 | G31: 100 | H31: 100 | I31: 100
A32: P5-30 | B32: Akta Kematian | C32: Pilar 5: Administrasi Kependudukan | D32: % | E32: 100 | F32: 100 | G32: 100 | H32: 100 | I32: 100

Sheet LOOKER_MASTER
A1: LOOKER_MASTER — Format Long: 1 baris per Indikator × Tahun | Kunci Blend: Kode + Tahun + Nama_OPD
A2: CARA PAKAI: Import ke Looker Studio → Data Source utama. Blend dengan LOOKER_RENAKSI via kolom Kode + Tahun + Nama_OPD. Metric pakai Average.
A3: Kode | B3: No_Pilar | C3: Nama_Pilar | D3: Nama_Indikator | E3: Satuan | F3: Nama_OPD | G3: Tahun | H3: Target | I3: Capaian | J3: Gap | K3: Pct_Gap | L3: Lower_Better | M3: Status_TL_Indikator | N3: Warna_TL | O3: Keterangan
A4: P1-01 | B4: 1 | C4: Pilar 1: Kuantitas Penduduk | D4: Total Fertility Rate (TFR) | E4: Anak/WUS | F4: DP3AKB | G4: 2025 | H4: 1.82 | I4: 1.96 | J4: =IFERROR(I4-H4,"") -> 0.14 | K4: =IFERROR(I4/H4-1,"") -> 0.076923077 | L4: Ya | M4: =IF(I4="","Belum Diisi",IF(I4<=H4,"On Track",IF(I4<=H4*1.1,"Warning","Alert"))) -> Warning | N4: =IF(I4="","Abu",IF(I4<=H4,"Hijau",IF(I4<=H4*1.1,"Kuning","Merah"))) -> Kuning | O4: Data tersedia
A5: P1-01 | B5: 1 | C5: Pilar 1: Kuantitas Penduduk | D5: Total Fertility Rate (TFR) | E5: Anak/WUS | F5: DP3AKB | G5: 2026 | H5: 1.83 | J5: =IFERROR(I5-H5,"") -> -1.83 | K5: =IFERROR(I5/H5-1,"") -> -1 | L5: Ya | M5: =IF(I5="","Belum Diisi",IF(I5<=H5,"On Track",IF(I5<=H5*1.1,"Warning","Alert"))) -> Belum Diisi | N5: =IF(I5="","Abu",IF(I5<=H5,"Hijau",IF(I5<=H5*1.1,"Kuning","Merah"))) -> Abu | O5: Menunggu laporan OPD
A6: P1-01 | B6: 1 | C6: Pilar 1: Kuantitas Penduduk | D6: Total Fertility Rate (TFR) | E6: Anak/WUS | F6: DP3AKB | G6: 2027 | H6: 1.84 | J6: =IFERROR(I6-H6,"") -> -1.84 | K6: =IFERROR(I6/H6-1,"") -> -1 | L6: Ya | M6: =IF(I6="","Belum Diisi",IF(I6<=H6,"On Track",IF(I6<=H6*1.1,"Warning","Alert"))) -> Belum Diisi | N6: =IF(I6="","Abu",IF(I6<=H6,"Hijau",IF(I6<=H6*1.1,"Kuning","Merah"))) -> Abu | O6: Menunggu laporan OPD
A7: P1-01 | B7: 1 | C7: Pilar 1: Kuantitas Penduduk | D7: Total Fertility Rate (TFR) | E7: Anak/WUS | F7: DP3AKB | G7: 2028 | H7: 1.85 | J7: =IFERROR(I7-H7,"") -> -1.85 | K7: =IFERROR(I7/H7-1,"") -> -1 | L7: Ya | M7: =IF(I7="","Belum Diisi",IF(I7<=H7,"On Track",IF(I7<=H7*1.1,"Warning","Alert"))) -> Belum Diisi | N7: =IF(I7="","Abu",IF(I7<=H7,"Hijau",IF(I7<=H7*1.1,"Kuning","Merah"))) -> Abu | O7: Menunggu laporan OPD
A8: P1-01 | B8: 1 | C8: Pilar 1: Kuantitas Penduduk | D8: Total Fertility Rate (TFR) | E8: Anak/WUS | F8: DP3AKB | G8: 2029 | H8: 1.85 | J8: =IFERROR(I8-H8,"") -> -1.85 | K8: =IFERROR(I8/H8-1,"") -> -1 | L8: Ya | M8: =IF(I8="","Belum Diisi",IF(I8<=H8,"On Track",IF(I8<=H8*1.1,"Warning","Alert"))) -> Belum Diisi | N8: =IF(I8="","Abu",IF(I8<=H8,"Hijau",IF(I8<=H8*1.1,"Kuning","Merah"))) -> Abu | O8: Menunggu laporan OPD
A9: P1-02 | B9: 1 | C9: Pilar 1: Kuantitas Penduduk | D9: ASFR 15-19 Tahun | E9: /1000 WUS | F9: DP3AKB | G9: 2025 | H9: 17.29 | I9: 14.4 | J9: =IFERROR(I9-H9,"") -> -2.89 | K9: =IFERROR(I9/H9-1,"") -> -0.16714864 | L9: Ya | M9: =IF(I9="","Belum Diisi",IF(I9<=H9,"On Track",IF(I9<=H9*1.1,"Warning","Alert"))) -> On Track | N9: =IF(I9="","Abu",IF(I9<=H9,"Hijau",IF(I9<=H9*1.1,"Kuning","Merah"))) -> Hijau | O9: Data tersedia
A10: P1-02 | B10: 1 | C10: Pilar 1: Kuantitas Penduduk | D10: ASFR 15-19 Tahun | E10: /1000 WUS | F10: DP3AKB | G10: 2026 | H10: 17 | J10: =IFERROR(I10-H10,"") -> -17 | K10: =IFERROR(I10/H10-1,"") -> -1 | L10: Ya | M10: =IF(I10="","Belum Diisi",IF(I10<=H10,"On Track",IF(I10<=H10*1.1,"Warning","Alert"))) -> Belum Diisi | N10: =IF(I10="","Abu",IF(I10<=H10,"Hijau",IF(I10<=H10*1.1,"Kuning","Merah"))) -> Abu | O10: Menunggu laporan OPD
A11: P1-02 | B11: 1 | C11: Pilar 1: Kuantitas Penduduk | D11: ASFR 15-19 Tahun | E11: /1000 WUS | F11: DP3AKB | G11: 2027 | H11: 17 | J11: =IFERROR(I11-H11,"") -> -17 | K11: =IFERROR(I11/H11-1,"") -> -1 | L11: Ya | M11: =IF(I11="","Belum Diisi",IF(I11<=H11,"On Track",IF(I11<=H11*1.1,"Warning","Alert"))) -> Belum Diisi | N11: =IF(I11="","Abu",IF(I11<=H11,"Hijau",IF(I11<=H11*1.1,"Kuning","Merah"))) -> Abu | O11: Menunggu laporan OPD
A12: P1-02 | B12: 1 | C12: Pilar 1: Kuantitas Penduduk | D12: ASFR 15-19 Tahun | E12: /1000 WUS | F12: DP3AKB | G12: 2028 | H12: 17 | J12: =IFERROR(I12-H12,"") -> -17 | K12: =IFERROR(I12/H12-1,"") -> -1 | L12: Ya | M12: =IF(I12="","Belum Diisi",IF(I12<=H12,"On Track",IF(I12<=H12*1.1,"Warning","Alert"))) -> Belum Diisi | N12: =IF(I12="","Abu",IF(I12<=H12,"Hijau",IF(I12<=H12*1.1,"Kuning","Merah"))) -> Abu | O12: Menunggu laporan OPD
A13: P1-02 | B13: 1 | C13: Pilar 1: Kuantitas Penduduk | D13: ASFR 15-19 Tahun | E13: /1000 WUS | F13: DP3AKB | G13: 2029 | H13: 17 | J13: =IFERROR(I13-H13,"") -> -17 | K13: =IFERROR(I13/H13-1,"") -> -1 | L13: Ya | M13: =IF(I13="","Belum Diisi",IF(I13<=H13,"On Track",IF(I13<=H13*1.1,"Warning","Alert"))) -> Belum Diisi | N13: =IF(I13="","Abu",IF(I13<=H13,"Hijau",IF(I13<=H13*1.1,"Kuning","Merah"))) -> Abu | O13: Menunggu laporan OPD
A14: P1-03 | B14: 1 | C14: Pilar 1: Kuantitas Penduduk | D14: Proporsi KB Modern | E14: % | F14: DP3AKB | G14: 2025 | H14: 77 | I14: 92.4 | J14: =IFERROR(I14-H14,"") -> 15.4 | K14: =IFERROR(I14/H14-1,"") -> 0.2 | L14: Tidak | M14: =IF(I14="","Belum Diisi",IF(I14>=H14,"On Track",IF(I14>=H14*0.9,"Warning","Alert"))) -> On Track | N14: =IF(I14="","Abu",IF(I14>=H14,"Hijau",IF(I14>=H14*0.9,"Kuning","Merah"))) -> Hijau | O14: Data tersedia
A15: P1-03 | B15: 1 | C15: Pilar 1: Kuantitas Penduduk | D15: Proporsi KB Modern | E15: % | F15: DP3AKB | G15: 2026 | H15: 77 | J15: =IFERROR(I15-H15,"") -> -77 | K15: =IFERROR(I15/H15-1,"") -> -1 | L15: Tidak | M15: =IF(I15="","Belum Diisi",IF(I15>=H15,"On Track",IF(I15>=H15*0.9,"Warning","Alert"))) -> Belum Diisi | N15: =IF(I15="","Abu",IF(I15>=H15,"Hijau",IF(I15>=H15*0.9,"Kuning","Merah"))) -> Abu | O15: Menunggu laporan OPD
A16: P1-03 | B16: 1 | C16: Pilar 1: Kuantitas Penduduk | D16: Proporsi KB Modern | E16: % | F16: DP3AKB | G16: 2027 | H16: 77 | J16: =IFERROR(I16-H16,"") -> -77 | K16: =IFERROR(I16/H16-1,"") -> -1 | L16: Tidak | M16: =IF(I16="","Belum Diisi",IF(I16>=H16,"On Track",IF(I16>=H16*0.9,"Warning","Alert"))) -> Belum Diisi | N16: =IF(I16="","Abu",IF(I16>=H16,"Hijau",IF(I16>=H16*0.9,"Kuning","Merah"))) -> Abu | O16: Menunggu laporan OPD
A17: P1-03 | B17: 1 | C17: Pilar 1: Kuantitas Penduduk | D17: Proporsi KB Modern | E17: % | F17: DP3AKB | G17: 2028 | H17: 77 | J17: =IFERROR(I17-H17,"") -> -77 | K17: =IFERROR(I17/H17-1,"") -> -1 | L17: Tidak | M17: =IF(I17="","Belum Diisi",IF(I17>=H17,"On Track",IF(I17>=H17*0.9,"Warning","Alert"))) -> Belum Diisi | N17: =IF(I17="","Abu",IF(I17>=H17,"Hijau",IF(I17>=H17*0.9,"Kuning","Merah"))) -> Abu | O17: Menunggu laporan OPD
A18: P1-03 | B18: 1 | C18: Pilar 1: Kuantitas Penduduk | D18: Proporsi KB Modern | E18: % | F18: DP3AKB | G18: 2029 | H18: 77 | J18: =IFERROR(I18-H18,"") -> -77 | K18: =IFERROR(I18/H18-1,"") -> -1 | L18: Tidak | M18: =IF(I18="","Belum Diisi",IF(I18>=H18,"On Track",IF(I18>=H18*0.9,"Warning","Alert"))) -> Belum Diisi | N18: =IF(I18="","Abu",IF(I18>=H18,"Hijau",IF(I18>=H18*0.9,"Kuning","Merah"))) -> Abu | O18: Menunggu laporan OPD
A19: P2-04 | B19: 2 | C19: Pilar 2: Kualitas Penduduk | D19: Rata-Rata Lama Sekolah | E19: Tahun | F19: Disdik | G19: 2025 | L19: Tidak | M19: Belum Diisi | N19: Abu | O19: Target belum ditetapkan
A20: P2-04 | B20: 2 | C20: Pilar 2: Kualitas Penduduk | D20: Rata-Rata Lama Sekolah | E20: Tahun | F20: Disdik | G20: 2026 | L20: Tidak | M20: Belum Diisi | N20: Abu | O20: Target belum ditetapkan
A21: P2-04 | B21: 2 | C21: Pilar 2: Kualitas Penduduk | D21: Rata-Rata Lama Sekolah | E21: Tahun | F21: Disdik | G21: 2027 | L21: Tidak | M21: Belum Diisi | N21: Abu | O21: Target belum ditetapkan
A22: P2-04 | B22: 2 | C22: Pilar 2: Kualitas Penduduk | D22: Rata-Rata Lama Sekolah | E22: Tahun | F22: Disdik | G22: 2028 | L22: Tidak | M22: Belum Diisi | N22: Abu | O22: Target belum ditetapkan
A23: P2-04 | B23: 2 | C23: Pilar 2: Kualitas Penduduk | D23: Rata-Rata Lama Sekolah | E23: Tahun | F23: Disdik | G23: 2029 | L23: Tidak | M23: Belum Diisi | N23: Abu | O23: Target belum ditetapkan
A24: P2-05 | B24: 2 | C24: Pilar 2: Kualitas Penduduk | D24: APK Perguruan Tinggi | E24: % | F24: Disdik | G24: 2025 | L24: Tidak | M24: Belum Diisi | N24: Abu | O24: Target belum ditetapkan
A25: P2-05 | B25: 2 | C25: Pilar 2: Kualitas Penduduk | D25: APK Perguruan Tinggi | E25: % | F25: Disdik | G25: 2026 | L25: Tidak | M25: Belum Diisi | N25: Abu | O25: Target belum ditetapkan
A26: P2-05 | B26: 2 | C26: Pilar 2: Kualitas Penduduk | D26: APK Perguruan Tinggi | E26: % | F26: Disdik | G26: 2027 | L26: Tidak | M26: Belum Diisi | N26: Abu | O26: Target belum ditetapkan
A27: P2-05 | B27: 2 | C27: Pilar 2: Kualitas Penduduk | D27: APK Perguruan Tinggi | E27: % | F27: Disdik | G27: 2028 | L27: Tidak | M27: Belum Diisi | N27: Abu | O27: Target belum ditetapkan
A28: P2-05 | B28: 2 | C28: Pilar 2: Kualitas Penduduk | D28: APK Perguruan Tinggi | E28: % | F28: Disdik | G28: 2029 | L28: Tidak | M28: Belum Diisi | N28: Abu | O28: Target belum ditetapkan
A29: P2-06 | B29: 2 | C29: Pilar 2: Kualitas Penduduk | D29: Pekerja Lulusan Sesuai Bidang | E29: % | F29: Disnaker | G29: 2025 | L29: Tidak | M29: Belum Diisi | N29: Abu | O29: Target belum ditetapkan
A30: P2-06 | B30: 2 | C30: Pilar 2: Kualitas Penduduk | D30: Pekerja Lulusan Sesuai Bidang | E30: % | F30: Disnaker | G30: 2026 | L30: Tidak | M30: Belum Diisi | N30: Abu | O30: Target belum ditetapkan
... A33: P2-06 | B33: 2 | C33: Pilar 2: Kualitas Penduduk | D33: Pekerja Lulusan Sesuai Bidang | E33: % | F33: Disnaker | G33: 2029 | L33: Tidak | M33: Belum Diisi | N33: Abu | O33: Target belum ditetapkan
A34: P2-07 | B34: 2 | C34: Pilar 2: Kualitas Penduduk | D34: Prevalensi Stunting | E34: % | F34: Dinkes | G34: 2025 | H34: 4.34 | I34: 7 | J34: =IFERROR(I34-H34,"") -> 2.66 | K34: =IFERROR(I34/H34-1,"") -> 0.61290323 | L34: Ya | M34: =IF(I34="","Belum Diisi",IF(I34<=H34,"On Track",IF(I34<=H34*1.1,"Warning","Alert"))) -> Alert | N34: =IF(I34="","Abu",IF(I34<=H34,"Hijau",IF(I34<=H34*1.1,"Kuning","Merah"))) -> Merah | O34: Menunggu laporan OPD
A35: P2-07 | B35: 2 | C35: Pilar 2: Kualitas Penduduk | D35: Prevalensi Stunting | E35: % | F35: Dinkes | G35: 2026 | H35: 4.27 | J35: =IFERROR(I35-H35,"") -> -4.27 | K35: =IFERROR(I35/H35-1,"") -> -1 | L35: Ya | M35: =IF(I35="","Belum Diisi",IF(I35<=H35,"On Track",IF(I35<=H35*1.1,"Warning","Alert"))) -> Belum Diisi | N35: =IF(I35="","Abu",IF(I35<=H35,"Hijau",IF(I35<=H35*1.1,"Kuning","Merah"))) -> Abu | O35: Menunggu laporan OPD
A36: P2-07 | B36: 2 | C36: Pilar 2: Kualitas Penduduk | D36: Prevalensi Stunting | E36: % | F36: Dinkes | G36: 2027 | H36: 4.24 | J36: =IFERROR(I36-H36,"") -> -4.24 | K36: =IFERROR(I36/H36-1,"") -> -1 | L36: Ya | M36: =IF(I36="","Belum Diisi",IF(I36<=H36,"On Track",IF(I36<=H36*1.1,"Warning","Alert"))) -> Belum Diisi | N36: =IF(I36="","Abu",IF(I36<=H36,"Hijau",IF(I36<=H36*1.1,"Kuning","Merah"))) -> Abu | O36: Menunggu laporan OPD
A37: P2-07 | B37: 2 | C37: Pilar 2: Kualitas Penduduk | D37: Prevalensi Stunting | E37: % | F37: Dinkes | G37: 2028 | H37: 4.22 | J37: =IFERROR(I37-H37,"") -> -4.22 | K37: =IFERROR(I37/H37-1,"") -> -1 | L37: Ya | M37: =IF(I37="","Belum Diisi",IF(I37<=H37,"On Track",IF(I37<=H37*1.1,"Warning","Alert"))) -> Belum Diisi | N37: =IF(I37="","Abu",IF(I37<=H37,"Hijau",IF(I37<=H37*1.1,"Kuning","Merah"))) -> Abu | O37: Menunggu laporan OPD
A38: P2-07 | B38: 2 | C38: Pilar 2: Kualitas Penduduk | D38: Prevalensi Stunting | E38: % | F38: Dinkes | G38: 2029 | H38: 4.15 | J38: =IFERROR(I38-H38,"") -> -4.15 | K38: =IFERROR(I38/H38-1,"") -> -1 | L38: Ya | M38: =IF(I38="","Belum Diisi",IF(I38<=H38,"On Track",IF(I38<=H38*1.1,"Warning","Alert"))) -> Belum Diisi | N38: =IF(I38="","Abu",IF(I38<=H38,"Hijau",IF(I38<=H38*1.1,"Kuning","Merah"))) -> Abu | O38: Menunggu laporan OPD
A39: P2-08 | B39: 2 | C39: Pilar 2: Kualitas Penduduk | D39: Angka Kematian Bayi (AKB) | E39: /1000 KH | F39: Dinkes | G39: 2025 | H39: 11.2 | J39: =IFERROR(I39-H39,"") -> -11.2 | K39: =IFERROR(I39/H39-1,"") -> -1 | L39: Ya | M39: =IF(I39="","Belum Diisi",IF(I39<=H39,"On Track",IF(I39<=H39*1.1,"Warning","Alert"))) -> Belum Diisi | N39: =IF(I39="","Abu",IF(I39<=H39,"Hijau",IF(I39<=H39*1.1,"Kuning","Merah"))) -> Abu | O39: Menunggu laporan OPD
A40: P2-08 | B40: 2 | C40: Pilar 2: Kualitas Penduduk | D40: Angka Kematian Bayi (AKB) | E40: /1000 KH | F40: Dinkes | G40: 2026 | H40: 11 | J40: =IFERROR(I40-H40,"") -> -11 | K40: =IFERROR(I40/H40-1,"") -> -1 | L40: Ya | M40: =IF(I40="","Belum Diisi",IF(I40<=H40,"On Track",IF(I40<=H40*1.1,"Warning","Alert"))) -> Belum Diisi | N40: =IF(I40="","Abu",IF(I40<=H40,"Hijau",IF(I40<=H40*1.1,"Kuning","Merah"))) -> Abu | O40: Menunggu laporan OPD
A41: P2-08 | B41: 2 | C41: Pilar 2: Kualitas Penduduk | D41: Angka Kematian Bayi (AKB) | E41: /1000 KH | F41: Dinkes | G41: 2027 | H41: 10.8 | J41: =IFERROR(I41-H41,"") -> -10.8 | K41: =IFERROR(I41/H41-1,"") -> -1 | L41: Ya | M41: =IF(I41="","Belum Diisi",IF(I41<=H41,"On Track",IF(I41<=H41*1.1,"Warning","Alert"))) -> Belum Diisi | N41: =IF(I41="","Abu",IF(I41<=H41,"Hijau",IF(I41<=H41*1.1,"Kuning","Merah"))) -> Abu | O41: Menunggu laporan OPD
A42: P2-08 | B42: 2 | C42: Pilar 2: Kualitas Penduduk | D42: Angka Kematian Bayi (AKB) | E42: /1000 KH | F42: Dinkes | G42: 2028 | H42: 10.6 | J42: =IFERROR(I42-H42,"") -> -10.6 | K42: =IFERROR(I42/H42-1,"") -> -1 | L42: Ya | M42: =IF(I42="","Belum Diisi",IF(I42<=H42,"On Track",IF(I42<=H42*1.1,"Warning","Alert"))) -> Belum Diisi | N42: =IF(I42="","Abu",IF(I42<=H42,"Hijau",IF(I42<=H42*1.1,"Kuning","Merah"))) -> Abu | O42: Menunggu laporan OPD
...

Sheet LOOKER_WIDE
A1: LOOKER_WIDE — 1 baris per Indikator (untuk Scorecard & Tabel tanpa redundan) | Kunci Blend: Kode + Nama_OPD
A2: CARA PAKAI: Gunakan untuk tabel 30 indikator dan scorecard. Blend dengan LOOKER_RENAKSI via Kode + Nama_OPD.
A3: Identifikasi | G3: Target per Tahun | L3: Capaian per Tahun (diisi OPD) | Q3: Gap & Status 2025
A4: No | B4: Kode | C4: No Pilar | D4: Nama Indikator | E4: Satuan | F4: Nama_OPD | G4: T_2025 | H4: T_2026 | I4: T_2027 | J4: T_2028 | K4: T_2029 | L4: C_2025 | M4: C_2026 | N4: C_2027 | O4: C_2028 | P4: C_2029 | Q4: Gap 2025 | R4: % Gap 2025 | S4: Status_TL 2025 | T4: Warna_TL 2025
A5: 1 | B5: P1-01 | C5: 1 | D5: Total Fertility Rate (TFR) | E5: Anak/WUS | F5: DP3AKB | G5: 1.82 | H5: 1.83 | I5: 1.84 | J5: 1.85 | K5: 1.85 | L5: 1.96 | Q5: =IFERROR(L5-G5,"") -> 0.14 | R5: =IFERROR(L5/G5-1,"") -> 0.076923077 | S5: =IF(L5="","Belum Diisi",IF(L5<=G5,"On Track",IF(L5<=G5*1.1,"Warning","Alert"))) -> Warning | T5: =IF(L5="","Abu",IF(L5<=G5,"Hijau",IF(L5<=G5*1.1,"Kuning","Merah"))) -> Kuning
A6: 2 | B6: P1-02 | C6: 1 | D6: ASFR 15-19 Tahun | E6: /1000 WUS | F6: DP3AKB | G6: 17.29 | H6: 17 | I6: 17 | J6: 17 | K6: 17 | L6: 14.4 | Q6: =IFERROR(L6-G6,"") -> -2.89 | R6: =IFERROR(L6/G6-1,"") -> -0.16714864 | S6: =IF(L6="","Belum Diisi",IF(L6<=G6,"On Track",IF(L6<=G6*1.1,"Warning","Alert"))) -> On Track | T6: =IF(L6="","Abu",IF(L6<=G6,"Hijau",IF(L6<=G6*1.1,"Kuning","Merah"))) -> Hijau
A7: 3 | B7: P1-03 | C7: 1 | D7: Proporsi KB Modern | E7: % | F7: DP3AKB | G7: 77 | H7: 77 | I7: 77 | J7: 77 | K7: 77 | L7: 92.4 | Q7: =IFERROR(L7-G7,"") -> 15.4 | R7: =IFERROR(L7/G7-1,"") -> 0.2 | S7: =IF(L7="","Belum Diisi",IF(L7>=G7,"On Track",IF(L7>=G7*0.9,"Warning","Alert"))) -> On Track | T7: =IF(L7="","Abu",IF(L7>=G7,"Hijau",IF(L7>=G7*0.9,"Kuning","Merah"))) -> Hijau
A8: 4 | B8: P2-04 | C8: 2 | D8: Rata-Rata Lama Sekolah | E8: Tahun | F8: Disdik
A9: 5 | B9: P2-05 | C9: 2 | D9: APK Perguruan Tinggi | E9: % | F9: Disdik
A10: 6 | B10: P2-06 | C10: 2 | D10: Pekerja Lulusan Sesuai Bidang | E10: % | F10: Disnaker
A11: 7 | B11: P2-07 | C11: 2 | D11: Prevalensi Stunting | E11: % | F11: Dinkes | G11: 4.34 | H11: 4.27 | I11: 4.24 | J11: 4.22 | K11: 4.15 | Q11: =IFERROR(L11-G11,"") -> -4.34 | R11: =IFERROR(L11/G11-1,"") -> -1 | S11: =IF(L11="","Belum Diisi",IF(L11<=G11,"On Track",IF(L11<=G11*1.1,"Warning","Alert"))) -> Belum Diisi | T11: =IF(L11="","Abu",IF(L11<=G11,"Hijau",IF(L11<=G11*1.1,"Kuning","Merah"))) -> Abu
A12: 8 | B12: P2-08 | C12: 2 | D12: Angka Kematian Bayi (AKB) | E12: /1000 KH | F12: Dinkes | G12: 11.2 | H12: 11 | I12: 10.8 | J12: 10.6 | K12: 10.4 | Q12: =IFERROR(L12-G12,"") -> -11.2 | R12: =IFERROR(L12/G12-1,"") -> -1 | S12: =IF(L12="","Belum Diisi",IF(L12<=G12,"On Track",IF(L12<=G12*1.1,"Warning","Alert"))) -> Belum Diisi | T12: =IF(L12="","Abu",IF(L12<=G12,"Hijau",IF(L12<=G12*1.1,"Kuning","Merah"))) -> Abu
A13: 9 | B13: P2-09 | C13: 2 | D13: Angka Kematian Ibu (AKI) | E13: /100.000 KH | F13: Dinkes | G13: 106 | H13: 105 | I13: 104 | J13: 103 | K13: 102 | Q13: =IFERROR(L13-G13,"") -> -106 | R13: =IFERROR(L13/G13-1,"") -> -1 | S13: =IF(L13="","Belum Diisi",IF(L13<=G13,"On Track",IF(L13<=G13*1.1,"Warning","Alert"))) -> Belum Diisi | T13: =IF(L13="","Abu",IF(L13<=G13,"Hijau",IF(L13<=G13*1.1,"Kuning","Merah"))) -> Abu
A14: 10 | B14: P2-10 | C14: 2 | D14: Tingkat Kemiskinan | E14: % | F14: Bappeda | G14: 8.38 | H14: 8.12 | I14: 7.85 | J14: 7.58 | K14: 7.31 | Q14: =IFERROR(L14-G14,"") -> -8.38 | R14: =IFERROR(L14/G14-1,"") -> -1 | S14: =IF(L14="","Belum Diisi",IF(L14<=G14,"On Track",IF(L14<=G14*1.1,"Warning","Alert"))) -> Belum Diisi | T14: =IF(L14="","Abu",IF(L14<=G14,"Hijau",IF(L14<=G14*1.1,"Kuning","Merah"))) -> Abu
A15: 11 | B15: P2-11 | C15: 2 | D15: TPAK Perempuan | E15: % | F15: Disnaker | G15: 54.41 | H15: 55.29 | I15: 56.18 | J15: 57.06 | K15: 57.95 | Q15: =IFERROR(L15-G15,"") -> -54.41 | R15: =IFERROR(L15/G15-1,"") -> -1 | S15: =IF(L15="","Belum Diisi",IF(L15>=G15,"On Track",IF(L15>=G15*0.9,"Warning","Alert"))) -> Belum Diisi | T15: =IF(L15="","Abu",IF(L15>=G15,"Hijau",IF(L15>=G15*0.9,"Kuning","Merah"))) -> Abu
A16: 12 | B16: P2-12 | C16: 2 | D16: Pekerja Informal | E16: % | F16: Disnaker | G16: 6.3 | H16: 6.31 | I16: 6.32 | J16: 6.33 | K16: 6.34 | Q16: =IFERROR(L16-G16,"") -> -6.3 | R16: =IFERROR(L16/G16-1,"") -> -1 | S16: =IF(L16="","Belum Diisi",IF(L16<=G16,"On Track",IF(L16<=G16*1.1,"Warning","Alert"))) -> Belum Diisi | T16: =IF(L16="","Abu",IF(L16<=G16,"Hijau",IF(L16<=G16*1.1,"Kuning","Merah"))) -> Abu
A17: 13 | B17: P2-13 | C17: 2 | D17: Penyandang Disabilitas Formal | E17: % | F17: Disnaker | G17: 0.024 | H17: 0.025 | I17: 0.026 | J17: 0.027 | K17: 0.028 | Q17: =IFERROR(L17-G17,"") -> -0.024 | R17: =IFERROR(L17/G17-1,"") -> -1 | S17: =IF(L17="","Belum Diisi",IF(L17>=G17,"On Track",IF(L17>=G17*0.9,"Warning","Alert"))) -> Belum Diisi | T17: =IF(L17="","Abu",IF(L17>=G17,"Hijau",IF(L17>=G17*0.9,"Kuning","Merah"))) -> Abu
A18: 14 | B18: P2-14 | C18: 2 | D18: Gini Ratio | E18: Indeks | F18: Bappeda | G18: 0.352 | H18: 0.341 | I18: 0.33 | J18: 0.319 | K18: 0.308 | Q18: =IFERROR(L18-G18,"") -> -0.352 | R18: =IFERROR(L18/G18-1,"") -> -1 | S18: =IF(L18="","Belum Diisi",IF(L18<=G18,"On Track",IF(L18<=G18*1.1,"Warning","Alert"))) -> Belum Diisi | T18: =IF(L18="","Abu",IF(L18<=G18,"Hijau",IF(L18<=G18*1.1,"Kuning","Merah"))) -> Abu
A19: 15 | B19: P2-15 | C19: 2 | D19: PDRB Per Kapita | E19: Rp Juta | F19: Bappeda
A20: 16 | B20: P2-16 | C20: 2 | D20: TPT (Pengangguran Terbuka) | E20: % | F20: Disnaker | G20: 3.38 | H20: 3.03 | I20: 2.96 | J20: 2.89 | K20: 2.82 | Q20: =IFERROR(L20-G20,"") -> -3.38 | R20: =IFERROR(L20/G20-1,"") -> -1 | S20: =IF(L20="","Belum Diisi",IF(L20<=G20,"On Track",IF(L20<=G20*1.1,"Warning","Alert"))) -> Belum Diisi | T20: =IF(L20="","Abu",IF(L20<=G20,"Hijau",IF(L20<=G20*1.1,"Kuning","Merah"))) -> Abu
A21: 17 | B21: P2-17 | C21: 2 | D21: Penambahan Wajib Pajak | E21: % | F21: BPPKAD
A22: 18 | B22: P3-18 | C22: 3 | D22: Indeks iBangga | E22: Indeks | F22: DP3AKB | G22: 60.5 | H22: 61 | I22: 61.5 | J22: 62 | K22: 62.5 | L22: 60.3 | Q22: =IFERROR(L22-G22,"") -> -0.2 | R22: =IFERROR(L22/G22-1,"") -> -0.0033057851 | S22: =IF(L22="","Belum Diisi",IF(L22>=G22,"On Track",IF(L22>=G22*0.9,"Warning","Alert"))) -> Warning | T22: =IF(L22="","Abu",IF(L22>=G22,"Hijau",IF(L22>=G22*0.9,"Kuning","Merah"))) -> Kuning
A23: 19 | B23: P3-19 | C23: 3 | D23: Indeks Perlindungan Anak | E23: Indeks | F23: DP3AKB | G23: 63.9 | H23: 64.1 | I23: 65.1 | J23: 66.1 | K23: 68.1 | Q23: =IFERROR(L23-G23,"") -> -63.9 | R23: =IFERROR(L23/G23-1,"") -> -1 | S23: =IF(L23="","Belum Diisi",IF(L23>=G23,"On Track",IF(L23>=G23*0.9,"Warning","Alert"))) -> Belum Diisi | T23: =IF(L23="","Abu",IF(L23>=G23,"Hijau",IF(L23>=G23*0.9,"Kuning","Merah"))) -> Abu
A24: 20 | B24: P3-20 | C24: 3 | D24: RT Akses Hunian Layak | E24: % | F24: Disperkim | G24: 17.35 | H24: 18.21 | I24: 19.03 | J24: 19.81 | K24: 20.49 | Q24: =IFERROR(L24-G24,"") -> -17.35 | R24: =IFERROR(L24/G24-1,"") -> -1 | S24: =IF(L24="","Belum Diisi",IF(L24>=G24,"On Track",IF(L24>=G24*0.9,"Warning","Alert"))) -> Belum Diisi | T24: =IF(L24="","Abu",IF(L24>=G24,"Hijau",IF(L24>=G24*0.9,"Kuning","Merah"))) -> Abu
A25: 21 | B25: P3-21 | C25: 3 | D25: RT Akses Sanitasi Aman | E25: % | F25: DPUPR | G25: 6.82 | H25: 7.13 | I25: 8.02 | J25: 9.31 | K25: 10.51 | Q25: =IFERROR(L25-G25,"") -> -6.82 | R25: =IFERROR(L25/G25-1,"") -> -1 | S25: =IF(L25="","Belum Diisi",IF(L25>=G25,"On Track",IF(L25>=G25*0.9,"Warning","Alert"))) -> Belum Diisi | T25: =IF(L25="","Abu",IF(L25>=G25,"Hijau",IF(L25>=G25*0.9,"Kuning","Merah"))) -> Abu
A26: 22 | B26: P3-22 | C26: 3 | D26: Indeks Lansia Berdaya | E26: Indeks | F26: DP3AKB | G26: 57.6 | H26: 57.6 | I26: 57.6 | J26: 57.6 | K26: 57.6 | L26: 70.2 | Q26: =IFERROR(L26-G26,"") -> 12.6 | R26: =IFERROR(L26/G26-1,"") -> 0.21875 | S26: =IF(L26="","Belum Diisi",IF(L26>=G26,"On Track",IF(L26>=G26*0.9,"Warning","Alert"))) -> On Track | T26: =IF(L26="","Abu",IF(L26>=G26,"Hijau",IF(L26>=G26*0.9,"Kuning","Merah"))) -> Hijau
A27: 23 | B27: P3-23 | C27: 3 | D27: Indeks Pengasuhan Remaja | E27: Indeks | F27: DP3AKB | G27: 79.9 | H27: 79.9 | I27: 79.9 | J27: 79.9 | K27: 79.9 | L27: 80.3 | Q27: =IFERROR(L27-G27,"") -> 0.4 | R27: =IFERROR(L27/G27-1,"") -> 0.0050062578 | S27: =IF(L27="","Belum Diisi",IF(L27>=G27,"On Track",IF(L27>=G27*0.9,"Warning","Alert"))) -> On Track | T27: =IF(L27="","Abu",IF(L27>=G27,"Hijau",IF(L27>=G27*0.9,"Kuning","Merah"))) -> Hijau
A28: 24 | B28: P3-24 | C28: 3 | D28: Cakupan JKN | E28: % | F28: Dinkes | G28: 87.36 | H28: 89.27 | I28: 91.18 | J28: 93.09 | K28: 95 | Q28: =IFERROR(L28-G28,"") -> -87.36 | R28: =IFERROR(L28/G28-1,"") -> -1 | S28: =IF(L28="","Belum Diisi",IF(L28>=G28,"On Track",IF(L28>=G28*0.9,"Warning","Alert"))) -> Belum Diisi | T28: =IF(L28="","Abu",IF(L28>=G28,"Hijau",IF(L28>=G28*0.9,"Kuning","Merah"))) -> Abu
A29: 25 | B29: P4-25 | C29: 4 | D29: Kampung KB Mandiri | E29: % | F29: DP3AKB | G29: 8.8 | H29: 10 | I29: 20 | J29: 30 | K29: 40 | Q29: =IFERROR(L29-G29,"") -> -8.8 | R29: =IFERROR(L29/G29-1,"") -> -1 | S29: =IF(L29="","Belum Diisi",IF(L29>=G29,"On Track",IF(L29>=G29*0.9,"Warning","Alert"))) -> Belum Diisi | T29: =IF(L29="","Abu",IF(L29>=G29,"Hijau",IF(L29>=G29*0.9,"Kuning","Merah"))) -> Abu
A30: 26 | B30: P4-26 | C30: 4 | D30: Kepadatan Penduduk | E30: Jiwa/km2 | F30: Dukcapil | G30: 628.28 | H30: 633.8 | I30: 638.7 | J30: 642.5 | K30: 645.3 | L30: 645 | Q30: =IFERROR(L30-G30,"") -> 16.72 | R30: =IFERROR(L30/G30-1,"") -> 0.026612338 | S30: =IF(L30="","Belum Diisi",IF(L30<=G30,"On Track",IF(L30<=G30*1.1,"Warning","Alert"))) -> Warning | T30: =IF(L30="","Abu",IF(L30<=G30,"Hijau",IF(L30<=G30*1.1,"Kuning","Merah"))) -> Kuning
A31: 27 | B31: P5-27 | C31: 5 | D31: Akta Kelahiran Balita | E31: % | F31: Dukcapil | G31: 99.55 | H31: 99.64 | I31: 99.73 | J31: 99.81 | K31: 99.9 | Q31: =IFERROR(L31-G31,"") -> -99.55 | R31: =IFERROR(L31/G31-1,"") -> -1 | S31: =IF(L31="","Belum Diisi",IF(L31>=G31,"On Track",IF(L31>=G31*0.9,"Warning","Alert"))) -> Belum Diisi | T31: =IF(L31="","Abu",IF(L31>=G31,"Hijau",IF(L31>=G31*0.9,"Kuning","Merah"))) -> Abu
A32: 28 | B32: P5-28 | C32: 5 | D32: Akta Cerai | E32: % | F32: Dukcapil | G32: 100 | H32: 100 | I32: 100 | J32: 100 | K32: 100 | Q32: =IFERROR(L32-G32,"") -> -100 | R32: =IFERROR(L32/G32-1,"") -> -1 | S32: =IF(L32="","Belum Diisi",IF(L32>=G32,"On Track",IF(L32>=G32*0.9,"Warning","Alert"))) -> Belum Diisi | T32: =IF(L32="","Abu",IF(L32>=G32,"Hijau",IF(L32>=G32*0.9,"Kuning","Merah"))) -> Abu
A33: 29 | B33: P5-29 | C33: 5 | D33: Akta Nikah | E33: % | F33: Dukcapil | G33: 100 | H33: 100 | I33: 100 | J33: 100 | K33: 100 | Q33: =IFERROR(L33-G33,"") -> -100 | R33: =IFERROR(L33/G33-1,"") -> -1 | S33: =IF(L33="","Belum Diisi",IF(L33>=G33,"On Track",IF(L33>=G33*0.9,"Warning","Alert"))) -> Belum Diisi | T33: =IF(L33="","Abu",IF(L33>=G33,"Hijau",IF(L33>=G33*0.9,"Kuning","Merah"))) -> Abu
A34: 30 | B34: P5-30 | C34: 5 | D34: Akta Kematian | E34: % | F34: Dukcapil | G34: 100 | H34: 100 | I34: 100 | J34: 100 | K34: 100 | Q34: =IFERROR(L34-G34,"") -> -100 | R34: =IFERROR(L34/G34-1,"") -> -1 | S34: =IF(L34="","Belum Diisi",IF(L34>=G34,"On Track",IF(L34>=G34*0.9,"Warning","Alert"))) -> Belum Diisi | T34: =IF(L34="","Abu",IF(L34>=G34,"Hijau",IF(L34>=G34*0.9,"Kuning","Merah"))) -> Abu

Sheet DATA_OPD
A1: DATA_OPD — Master OPD & Indikator yang Dipegang | Kunci Blend: Nama_OPD + Kode
A2: INPUT: Isi kolom Status OPD bebas. Nama_OPD HARUS SAMA PERSIS dengan LOOKER_MASTER & LOOKER_RENAKSI (case sensitive). Tidak mempengaruhi skor.
A3: No | B3: Nama_OPD | C3: No Pilar | D3: Nama Indikator | E3: Kode | F3: Status OPD (keterangan bebas) | G3: Lower Better | H3: Kolaborasi OPD
A4: 1 | B4: BPPKAD | C4: 2 | D4: Penambahan Wajib Pajak | E4: P2-17 | G4: Tidak
A5: 2 | B5: Bappeda | C5: 2 | D5: Tingkat Kemiskinan | E5: P2-10 | G5: Ya
A6: 3 | B6: Bappeda | C6: 2 | D6: Gini Ratio | E6: P2-14 | G6: Ya
A7: 4 | B7: Bappeda | C7: 2 | D7: PDRB Per Kapita | E7: P2-15 | G7: Tidak
A8: 5 | B8: DP3AKB | C8: 1 | D8: Total Fertility Rate (TFR) | E8: P1-01 | G8: Ya
A9: 6 | B9: DP3AKB | C9: 1 | D9: ASFR 15-19 Tahun | E9: P1-02 | G9: Ya
A10: 7 | B10: DP3AKB | C10: 1 | D10: Proporsi KB Modern | E10: P1-03 | G10: Tidak
A11: 8 | B11: DP3AKB | C11: 3 | D11: Indeks iBangga | E11: P3-18 | G11: Tidak
A12: 9 | B12: DP3AKB | C12: 3 | D12: Indeks Perlindungan Anak | E12: P3-19 | G12: Tidak
A13: 10 | B13: DP3AKB | C13: 3 | D13: Indeks Lansia Berdaya | E13: P3-22 | G13: Tidak
A14: 11 | B14: DP3AKB | C14: 3 | D14: Indeks Pengasuhan Remaja | E14: P3-23 | G14: Tidak
A15: 12 | B15: DP3AKB | C15: 4 | D15: Kampung KB Mandiri | E15: P4-25 | G15: Tidak
... A33: 30 | B33: Dukcapil | C33: 5 | D33: Akta Kematian | E33: P5-30 | G33: Tidak
A34: 💡 Contoh Status OPD: 'Aktif melaporkan', 'Menunggu data', 'Kolaborasi aktif'. ⚠️ Nama_OPD di kolom B harus persis sama dengan di LOOKER_MASTER dan DATA_RENAKSI.

Sheet DATA_RENAKSI
A1: DATA_RENAKSI — Input Rencana Aksi OPD | Nama_OPD + Kode + Tahun = kunci link ke LOOKER_RENAKSI
A2: INPUT: Tambah baris baru untuk setiap kegiatan. Status WAJIB persis: 'Terlaksana' atau 'Tidak Terlaksana'. Nama_OPD HARUS SAMA PERSIS dengan kolom Nama_OPD di LOOKER_MASTER.
A3: No | B3: Nama_OPD | C3: No Pilar | D3: Nama Indikator | E3: Kode | F3: Tahun | G3: Nama Kegiatan / Rencana Aksi | H3: Status (Terlaksana / Tidak Terlaksana) | I3: Keterangan | J3: Kolaborasi OPD
A4: 1 | B4: DP3AKB | C4: 1 | D4: Total Fertility Rate (TFR) | E4: P1-01 | F4: 2025 | G4: Publikasi data TFR kabupaten | H4: Terlaksana | I4: Dipresentasikan di rapat PJPK | J4: —
A5: 2 | B5: DP3AKB | C5: 1 | D5: Total Fertility Rate (TFR) | E5: P1-01 | F5: 2025 | G5: Monitoring peserta KB aktif | H5: Terlaksana | I5: Data divalidasi bersama Puskesmas | J5: —
A6: 3 | B6: DP3AKB | C6: 1 | D6: Total Fertility Rate (TFR) | E6: P1-01 | F6: 2025 | G6: Sosialisasi KB ke kecamatan | H6: Tidak Terlaksana | I6: Anggaran belum cair | J6: —
A7: 4 | B7: DP3AKB | C7: 1 | D7: Proporsi KB Modern | E7: P1-03 | F7: 2025 | G7: Distribusi alat KB gratis | H7: Terlaksana | I7: 18 kecamatan terlayani | J7: —
A8: 5 | B8: DP3AKB | C8: 1 | D8: Proporsi KB Modern | E8: P1-03 | F8: 2025 | G8: Pelatihan bidan KB | H8: Terlaksana | I8: 120 bidan terlatih | J8: —
A9: 6 | B9: Dinkes | C9: 2 | D9: Prevalensi Stunting | E9: P2-07 | F9: 2025 | G9: Survei stunting tingkat desa | H9: Terlaksana | I9: 15 desa sudah disurvei | J9: —
A10: 7 | B10: Dinkes | C10: 2 | D10: Prevalensi Stunting | E10: P2-07 | F10: 2025 | G10: Pelatihan kader posyandu | H10: Terlaksana | I10: 200 kader terlatih | J10: —
A11: 8 | B11: Dinkes | C11: 2 | D11: Prevalensi Stunting | E11: P2-07 | F11: 2025 | G11: Perbaikan gizi balita | H11: Tidak Terlaksana | I11: Menunggu distribusi PMT | J11: —
A12: 9 | B12: DP3AKB | C12: 3 | D12: Indeks iBangga | E12: P3-18 | F12: 2025 | G12: Pengumpulan data iBangga | H12: Terlaksana | I12: 18 kecamatan selesai | J12: —
A13: 10 | B13: DP3AKB | C13: 3 | D13: Indeks iBangga | E13: P3-18 | F13: 2025 | G13: Verifikasi data lapangan | H13: Tidak Terlaksana | I13: Petugas belum lengkap | J13: Dinkes
A14: 11 | B14: Dukcapil | C14: 5 | D14: Akta Kelahiran Balita | E14: P5-27 | F14: 2025 | G14: Jemput bola akta kelahiran | H14: Terlaksana | I14: 5.000 balita terlayani | J14: —
A15: 12 | B15: Dukcapil | C15: 5 | D15: Akta Kelahiran Balita | E15: P5-27 | F15: 2025 | G15: Sosialisasi kepemilikan akta | H15: Terlaksana | I15: Di 18 kecamatan | J15: —
A16: 13 | B16: Dukcapil | C16: 5 | D16: Akta Kelahiran Balita | E16: P5-27 | F16: 2025 | G16: Integrasi data RS-Dukcapil | H16: Terlaksana | I16: Sistem sudah terhubung | J16: Dinkes
A33: 💡 Cara tambah kegiatan: tambah baris baru, isi kolom A-J. Status WAJIB: 'Terlaksana' atau 'Tidak Terlaksana' (persis). LOOKER_RENAKSI otomatis menghitung ulang. ⚠️ Nama_OPD harus persis sama dengan di LOOKER_MASTER.

Sheet LOOKER_RENAKSI
A1: LOOKER_RENAKSI — Agregasi Rencana Aksi | Kunci Blend: Nama_OPD + Kode + Tahun + Nama_Pilar
A2: ⚠️ FORMULA SHEET — Kolom H-L otomatis dari DATA_RENAKSI. Jangan edit manual kolom H-L. Tambah baris baru jika ada kombinasi Nama_OPD+Kode+Tahun baru. Nama_Pilar wajib diisi teks lengkap.
A3: No | B3: Nama_OPD | C3: No Pilar | D3: Nama_Pilar | E3: Nama Indikator | F3: Kode | G3: Tahun | H3: Total Kegiatan | I3: Terlaksana | J3: % Terlaksana | K3: Status Traffic Light | L3: Data Lengkap
A4: 1 | B4: DP3AKB | C4: 1 | D4: Pilar 1: Kuantitas Penduduk | E4: Total Fertility Rate (TFR) | F4: P1-01 | G4: 2025 | H4: =COUNTIFS(DATA_RENAKSI!$B$4:$B$200,B4,DATA_RENAKSI!$E$4:$E$200,F4,DATA_RENAKSI!$F$4:$F$200,G4) -> 3 | I4: =COUNTIFS(DATA_RENAKSI!$B$4:$B$200,B4,DATA_RENAKSI!$E$4:$E$200,F4,DATA_RENAKSI!$F$4:$F$200,G4,DATA_RENAKSI!$H$4:$H$200,"Terlaksana") -> 2 | J4: =IFERROR(I4/H4,0) -> 0.66666667 | K4: =IF(H4=0,"Belum Diisi",IF(J4>=0.8,"On Track",IF(J4>=0.6,"Warning","Alert"))) -> Warning | L4: =IF(H4=0,"Belum Diisi",IF(COUNTIFS(DATA_RENAKSI!$B$4:$B$200,B4,DATA_RENAKSI!$E$4:$E$200,F4,DATA_RENAKSI!$F$4:$F$200,G4,DATA_RENAKSI!$H$4:$H$200,"")=0,"✅ Lengkap","❌ Ada yang kosong")) -> ✅ Lengkap
A5: 2 | B5: DP3AKB | C5: 1 | D5: Pilar 1: Kuantitas Penduduk | E5: Proporsi KB Modern | F5: P1-03 | G5: 2025 | H5: =COUNTIFS(DATA_RENAKSI!$B$4:$B$200,B5,DATA_RENAKSI!$E$4:$E$200,F5,DATA_RENAKSI!$F$4:$F$200,G5) -> 2 | I5: =COUNTIFS(DATA_RENAKSI!$B$4:$B$200,B5,DATA_RENAKSI!$E$4:$E$200,F5,DATA_RENAKSI!$F$4:$F$200,G5,DATA_RENAKSI!$H$4:$H$200,"Terlaksana") -> 2 | J5: =IFERROR(I5/H5,0) -> 1 | K5: =IF(H5=0,"Belum Diisi",IF(J5>=0.8,"On Track",IF(J5>=0.6,"Warning","Alert"))) -> On Track | L5: =IF(H5=0,"Belum Diisi",IF(COUNTIFS(DATA_RENAKSI!$B$4:$B$200,B5,DATA_RENAKSI!$E$4:$E$200,F5,DATA_RENAKSI!$F$4:$F$200,G5,DATA_RENAKSI!$H$4:$H$200,"")=0,"✅ Lengkap","❌ Ada yang kosong")) -> ✅ Lengkap
A6: 3 | B6: Dinkes | C6: 2 | D6: Pilar 2: Kualitas Penduduk | E6: Prevalensi Stunting | F6: P2-07 | G6: 2025 | H6: =COUNTIFS(DATA_RENAKSI!$B$4:$B$200,B6,DATA_RENAKSI!$E$4:$E$200,F6,DATA_RENAKSI!$F$4:$F$200,G6) -> 3 | I6: =COUNTIFS(DATA_RENAKSI!$B$4:$B$200,B6,DATA_RENAKSI!$E$4:$E$200,F6,DATA_RENAKSI!$F$4:$F$200,G6,DATA_RENAKSI!$H$4:$H$200,"Terlaksana") -> 2 | J6: =IFERROR(I6/H6,0) -> 0.66666667 | K6: =IF(H6=0,"Belum Diisi",IF(J6>=0.8,"On Track",IF(J6>=0.6,"Warning","Alert"))) -> Warning | L6: =IF(H6=0,"Belum Diisi",IF(COUNTIFS(DATA_RENAKSI!$B$4:$B$200,B6,DATA_RENAKSI!$E$4:$E$200,F6,DATA_RENAKSI!$F$4:$F$200,G6,DATA_RENAKSI!$H$4:$H$200,"")=0,"✅ Lengkap","❌ Ada yang kosong")) -> ✅ Lengkap
A7: 4 | B7: Dinkes | C7: 2 | D7: Pilar 2: Kualitas Penduduk | E7: Angka Kematian Bayi (AKB) | F7: P2-08 | G7: 2025 | H7: =COUNTIFS(DATA_RENAKSI!$B$4:$B$200,B7,DATA_RENAKSI!$E$4:$E$200,F7,DATA_RENAKSI!$F$4:$F$200,G7) -> 0 | I7: =COUNTIFS(DATA_RENAKSI!$B$4:$B$200,B7,DATA_RENAKSI!$E$4:$E$200,F7,DATA_RENAKSI!$F$4:$F$200,G7,DATA_RENAKSI!$H$4:$H$200,"Terlaksana") -> 0 | J7: =IFERROR(I7/H7,0) -> 0 | K7: =IF(H7=0,"Belum Diisi",IF(J7>=0.8,"On Track",IF(J7>=0.6,"Warning","Alert"))) -> Belum Diisi | L7: =IF(H7=0,"Belum Diisi",IF(COUNTIFS(DATA_RENAKSI!$B$4:$B$200,B7,DATA_RENAKSI!$E$4:$E$200,F7,DATA_RENAKSI!$F$4:$F$200,G7,DATA_RENAKSI!$H$4:$H$200,"")=0,"✅ Lengkap","❌ Ada yang kosong")) -> Belum Diisi
A8: 5 | B8: Bappeda | C8: 2 | D8: Pilar 2: Kualitas Penduduk | E8: Tingkat Kemiskinan | F8: P2-10 | G8: 2025 | H8: =COUNTIFS(DATA_RENAKSI!$B$4:$B$200,B8,DATA_RENAKSI!$E$4:$E$200,F8,DATA_RENAKSI!$F$4:$F$200,G8) -> 0 | I8: =COUNTIFS(DATA_RENAKSI!$B$4:$B$200,B8,DATA_RENAKSI!$E$4:$E$200,F8,DATA_RENAKSI!$F$4:$F$200,G8,DATA_RENAKSI!$H$4:$H$200,"Terlaksana") -> 0 | J8: =IFERROR(I8/H8,0) -> 0 | K8: =IF(H8=0,"Belum Diisi",IF(J8>=0.8,"On Track",IF(J8>=0.6,"Warning","Alert"))) -> Belum Diisi | L8: =IF(H8=0,"Belum Diisi",IF(COUNTIFS(DATA_RENAKSI!$B$4:$B$200,B8,DATA_RENAKSI!$E$4:$E$200,F8,DATA_RENAKSI!$F$4:$F$200,G8,DATA_RENAKSI!$H$4:$H$200,"")=0,"✅ Lengkap","❌ Ada yang kosong")) -> Belum Diisi
A9: 6 | B9: DP3AKB | C9: 3 | D9: Pilar 3: Pembangunan Keluarga | E9: Indeks iBangga | F9: P3-18 | G9: 2025 | H9: =COUNTIFS(DATA_RENAKSI!$B$4:$B$200,B9,DATA_RENAKSI!$E$4:$E$200,F9,DATA_RENAKSI!$F$4:$F$200,G9) -> 2 | I9: =COUNTIFS(DATA_RENAKSI!$B$4:$B$200,B9,DATA_RENAKSI!$E$4:$E$200,F9,DATA_RENAKSI!$F$4:$F$200,G9,DATA_RENAKSI!$H$4:$H$200,"Terlaksana") -> 1 | J9: =IFERROR(I9/H9,0) -> 0.5 | K9: =IF(H9=0,"Belum Diisi",IF(J9>=0.8,"On Track",IF(J9>=0.6,"Warning","Alert"))) -> Alert | L9: =IF(H9=0,"Belum Diisi",IF(COUNTIFS(DATA_RENAKSI!$B$4:$B$200,B9,DATA_RENAKSI!$E$4:$E$200,F9,DATA_RENAKSI!$F$4:$F$200,G9,DATA_RENAKSI!$H$4:$H$200,"")=0,"✅ Lengkap","❌ Ada yang kosong")) -> ✅ Lengkap
A10: 7 | B10: Dukcapil | C10: 5 | D10: Pilar 5: Administrasi Kependudukan | E10: Akta Kelahiran Balita | F10: P5-27 | G10: 2025 | H10: =COUNTIFS(DATA_RENAKSI!$B$4:$B$200,B10,DATA_RENAKSI!$E$4:$E$200,F10,DATA_RENAKSI!$F$4:$F$200,G10) -> 3 | I10: =COUNTIFS(DATA_RENAKSI!$B$4:$B$200,B10,DATA_RENAKSI!$E$4:$E$200,F10,DATA_RENAKSI!$F$4:$F$200,G10,DATA_RENAKSI!$H$4:$H$200,"Terlaksana") -> 3 | J10: =IFERROR(I10/H10,0) -> 1 | K10: =IF(H10=0,"Belum Diisi",IF(J10>=0.8,"On Track",IF(J10>=0.6,"Warning","Alert"))) -> On Track | L10: =IF(H10=0,"Belum Diisi",IF(COUNTIFS(DATA_RENAKSI!$B$4:$B$200,B10,DATA_RENAKSI!$E$4:$E$200,F10,DATA_RENAKSI!$F$4:$F$200,G10,DATA_RENAKSI!$H$4:$H$200,"")=0,"✅ Lengkap","❌ Ada yang kosong")) -> ✅ Lengkap
A11: 8 | B11: Dukcapil | C11: 5 | D11: Pilar 5: Administrasi Kependudukan | E11: Akta Cerai | F11: P5-28 | G11: 2025 | H11: =COUNTIFS(DATA_RENAKSI!$B$4:$B$200,B11,DATA_RENAKSI!$E$4:$E$200,F11,DATA_RENAKSI!$F$4:$F$200,G11) -> 0 | I11: =COUNTIFS(DATA_RENAKSI!$B$4:$B$200,B11,DATA_RENAKSI!$E$4:$E$200,F11,DATA_RENAKSI!$F$4:$F$200,G11,DATA_RENAKSI!$H$4:$H$200,"Terlaksana") -> 0 | J11: =IFERROR(I11/H11,0) -> 0 | K11: =IF(H11=0,"Belum Diisi",IF(J11>=0.8,"On Track",IF(J11>=0.6,"Warning","Alert"))) -> Belum Diisi | L11: =IF(H11=0,"Belum Diisi",IF(COUNTIFS(DATA_RENAKSI!$B$4:$B$200,B11,DATA_RENAKSI!$E$4:$E$200,F11,DATA_RENAKSI!$F$4:$F$200,G11,DATA_RENAKSI!$H$4:$H$200,"")=0,"✅ Lengkap","❌ Ada yang kosong")) -> Belum Diisi
A12: 💡 Cara tambah baris: copy 1 baris → paste di bawah → edit Nama_OPD (B), Kode (F), Tahun (G) → kolom H-L otomatis hitung. Blend di Looker Studio: join key = Nama_OPD + Kode + Tahun.

Sheet TUTORIAL BLEND LOOKER
A1: TUTORIAL FINAL: Satu Filter Mengontrol Semua Data — Setup Data Blending di Looker Studio
A2: KONSEP: MENGAPA BLEND?
A3: → | B3: Filter OPD → kontrol semua komponen sekaligus | C3: Tanpa blend: filter di chart A tidak mempengaruhi chart B. Dengan blend: satu filter OPD klik → tabel indikator + tabel renaksi + scorecard + chart SEMUA ikut berubah. | D3: Ini inti dari permintaan Anda
A4: LANGKAH 1: CONNECT 3 DATA SOURCE
A5: 1 | B5: Connect LOOKER_MASTER | C5: Resource → Manage data sources → + Add → Google Sheets → LOOKER_MASTER → Connect | D5: Data source utama
A6: 2 | B6: Connect LOOKER_WIDE | C6: Ulangi → pilih sheet LOOKER_WIDE → Connect | D6: Untuk tabel 30 baris tanpa redundan
A7: 3 | B7: Connect LOOKER_RENAKSI | C7: Ulangi → pilih sheet LOOKER_RENAKSI → Connect | D7: Untuk tabel rencana aksi
A8: LANGKAH 2: BUAT BLENDED DATA SOURCE
A9: 4 | B9: Buka menu Blend | C9: Resource → Manage blended data → + Add a data blend | D9: —
A10: 5 | B10: Blend 1: MASTER + RENAKSI | C10: Data source 1: LOOKER_MASTER | Data source 2: LOOKER_RENAKSI | D10: Untuk chart yang butuh data indikator + renaksi
A11: 6 | B11: Set Join Key Blend 1 | C11: Join condition: Nama_OPD = Nama_OPD | Kode = Kode | Tahun = Tahun | D11: Ketiga kolom ini HARUS SAMA PERSIS nilainya
A12: 7 | B12: Join type: Left Outer | C12: Pilih Left Outer Join → semua indikator tetap muncul walau belum ada renaksinya | D12: —
A13: 8 | B13: Blend 2: WIDE + RENAKSI | C13: Buat blend baru → Data source 1: LOOKER_WIDE | Data source 2: LOOKER_RENAKSI | D13: Join key: Nama_OPD + Kode (tanpa Tahun karena WIDE tidak punya kolom Tahun)
A14: LANGKAH 3: BUAT FILTER CONTROL TERPUSAT
A15: 9 | B15: Insert Filter Control: OPD | C15: Insert → Filter Control → drag di pojok kiri atas dashboard | D15: —
A16: 10 | B16: Set Dimension Filter OPD | C16: Data source: LOOKER_MASTER → Dimension: Nama_OPD | D16: —
A17: 11 | B17: Insert Filter Control: Pilar | C17: Insert → Filter Control → Dimension: Nama_Pilar → Data source: LOOKER_MASTER | D17: —
A18: 12 | B18: Insert Filter Control: Tahun | C18: Insert → Filter Control → Dimension: Tahun → Data source: LOOKER_MASTER | D18: —
A19: 13 | B19: Insert Filter Control: Status TL | C19: Insert → Filter Control → Dimension: Status_TL_Indikator → Data source: LOOKER_MASTER | D19: —
A20: LANGKAH 4: HUBUNGKAN FILTER KE SEMUA KOMPONEN
A21: 14 | B21: Klik komponen chart/tabel manapun | C21: Klik chart → di panel kanan scroll ke bawah → cari 'Filter' section | D21: —
A22: 15 | B22: Tambahkan Cross-filter | C22: Klik 'Add a cross-filter' → pilih filter yang sudah dibuat (OPD, Pilar, Tahun, Status) | D22: Lakukan untuk SETIAP chart dan tabel
A23: 16 | B23: Verifikasi koneksi | C23: Klik filter OPD = 'Dinkes' → semua chart harus berubah sekaligus | D23: Jika ada yang tidak berubah → cek apakah join key sudah benar
A24: LANGKAH 5: BUAT KOMPONEN DASHBOARD
A25: 17 | B25: Tabel indikator (30 baris) | C25: Data source: LOOKER_WIDE | Dimension: Kode, Nama Indikator, Nama_OPD | Metric: T_2025, C_2025, Gap 2025, Status_TL | D25: —
A26: 18 | B26: Tabel rencana aksi | C26: Data source: LOOKER_RENAKSI | Dimension: Nama_OPD, Kode, Tahun, Nama Kegiatan | Metric: % Terlaksana (Avg), Status TL | D26: —
A27: 19 | B27: Scorecard On Track indikator | C27: Data source: LOOKER_MASTER | Metric: Record Count | Filter: Status_TL_Indikator = On Track AND Tahun = 2025 | D27: —
A28: 20 | B28: Scorecard On Track renaksi | C28: Data source: LOOKER_RENAKSI | Metric: Record Count | Filter: Status Traffic Light = On Track | D28: —
A29: 21 | B29: Bar chart % keterlaksanaan OPD | C29: Data source: LOOKER_RENAKSI | Dimension: Nama_OPD | Metric: % Terlaksana (Average) | D29: —
A30: 22 | B30: Line chart tren indikator | C30: Data source: LOOKER_MASTER | Dimension: Tahun | Metric: Target (Avg), Capaian (Avg) | Filter: Kode = pilihan | D30: Tambahkan Filter Control Kode agar bisa ganti indikator
A31: LANGKAH 6: UPDATE DATA SETIAP TAHUN
A32: 23 | B32: Tambah data renaksi 2026 | C32: Buka Google Sheets → DATA_RENAKSI → tambah baris baru → Tahun=2026 | D32: —
A33: 24 | B33: Tambah baris LOOKER_RENAKSI 2026 | C33: LOOKER_RENAKSI → copy baris ada → paste → edit Tahun=2026 → H-L otomatis hitung | D33: —
A34: 25 | B34: Ganti Filter Tahun ke 2026 | C34: Di Looker Studio → klik Filter Control Tahun → pilih 2026 → semua update otomatis | D34: Tidak perlu konfigurasi ulang apapun
A35: CATATAN PENTING — JAGA KONSISTENSI NAMA
A36: → | B36: Nama_OPD HARUS SAMA PERSIS di semua sheet | C36: Contoh: 'DP3AKB' di LOOKER_MASTER harus persis 'DP3AKB' di DATA_RENAKSI dan LOOKER_RENAKSI. Jika berbeda (misal 'dp3akb' atau 'DP3 AKB') maka blend tidak akan menemukan pasangannya. | D36: ⚠️ Ini penyebab blend tidak bekerja paling umum
A37: → | B37: Kode HARUS SAMA PERSIS di semua sheet | C37: Contoh: 'P1-01' bukan 'p1-01' atau 'P1 01'. Gunakan copy-paste jangan ketik ulang. | D37: ⚠️ Cek ini jika filter tidak bekerja
